<sdf version='1.6'>
  <world name='default'>
    <model name='ground_plane'>
      <static>1</static>
      <link name='link'>
        <collision name='collision'>
          <geometry>
            <plane>
              <normal>0 0 1</normal>
              <size>100 100</size>
            </plane>
          </geometry>
          <surface>
            <contact>
              <collide_bitmask>65535</collide_bitmask>
              <ode/>
            </contact>
            <friction>
              <ode>
                <mu>100</mu>
                <mu2>50</mu2>
              </ode>
              <torsional>
                <ode/>
              </torsional>
            </friction>
            <bounce/>
          </surface>
          <max_contacts>10</max_contacts>
        </collision>
        <visual name='visual'>
          <cast_shadows>0</cast_shadows>
          <geometry>
            <plane>
              <normal>0 0 1</normal>
              <size>100 100</size>
            </plane>
          </geometry>
          <material>
            <script>
              <uri>file://media/materials/scripts/gazebo.material</uri>
              <name>Gazebo/Grey</name>
            </script>
          </material>
        </visual>
        <self_collide>0</self_collide>
        <enable_wind>0</enable_wind>
        <kinematic>0</kinematic>
      </link>
    </model>
    <light name='sun' type='directional'>
      <cast_shadows>1</cast_shadows>
      <pose frame=''>0 0 10 0 -0 0</pose>
      <diffuse>0.8 0.8 0.8 1</diffuse>
      <specular>0.2 0.2 0.2 1</specular>
      <attenuation>
        <range>1000</range>
        <constant>0.9</constant>
        <linear>0.01</linear>
        <quadratic>0.001</quadratic>
      </attenuation>
      <direction>-0.5 0.1 -0.9</direction>
    </light>
    <gravity>0 0 -9.8</gravity>
    <magnetic_field>6e-06 2.3e-05 -4.2e-05</magnetic_field>
    <atmosphere type='adiabatic'/>
    <physics name='default_physics' default='0' type='ode'>
      <max_step_size>0.001</max_step_size>
      <real_time_factor>1</real_time_factor>
      <real_time_update_rate>1000</real_time_update_rate>
    </physics>
    <scene>
      <ambient>0.4 0.4 0.4 1</ambient>
      <background>0.7 0.7 0.7 1</background>
      <shadows>1</shadows>
    </scene>
    <audio>
      <device>default</device>
    </audio>
    <wind/>
    <spherical_coordinates>
      <surface_model>EARTH_WGS84</surface_model>
      <latitude_deg>0</latitude_deg>
      <longitude_deg>0</longitude_deg>
      <elevation>0</elevation>
      <heading_deg>0</heading_deg>
    </spherical_coordinates>
    <model name='rrt_bot'>
      <link name='chassis'>
        <pose frame=''>0 0 0 0 -0 0</pose>
        <inertial>
          <pose frame=''>0 0 0.1 0 -0 0</pose>
          <mass>15</mass>
          <inertia>
            <ixx>0.1</ixx>
            <ixy>0</ixy>
            <ixz>0</ixz>
            <iyy>0.1</iyy>
            <iyz>0</iyz>
            <izz>0.1</izz>
          </inertia>
        </inertial>
        <collision name='chassis_fixed_joint_lump__collision_collision'>
          <pose frame=''>0 0 0 0 -0 0</pose>
          <geometry>
            <box>
              <size>0.4 0.2 0.1</size>
            </box>
          </geometry>
          <max_contacts>10</max_contacts>
          <surface>
            <contact>
              <ode/>
            </contact>
            <bounce/>
            <friction>
              <torsional>
                <ode/>
              </torsional>
              <ode/>
            </friction>
          </surface>
        </collision>
        <visual name='chassis_visual_visual'>
          <pose frame=''>0 0 0 0 -0 0</pose>
          <geometry>
            <box>
              <size>0.4 0.2 0.1</size>
            </box>
          </geometry>
          <material>
            <script>
              <name>Gazebo/Black</name>
              <uri>file://media/materials/scripts/gazebo.material</uri>
            </script>
          </material>
        </visual>
        <gravity>1</gravity>
        <velocity_decay/>
        <self_collide>0</self_collide>
        <enable_wind>0</enable_wind>
        <kinematic>0</kinematic>
      </link>
      <link name='left_fwheel'>
        <pose frame=''>-0.1 0.15 0 0 -0 0</pose>
        <inertial>
          <pose frame=''>0 0 0 -0 1.5707 1.5707</pose>
          <mass>5</mass>
          <inertia>
            <ixx>0.013</ixx>
            <ixy>0</ixy>
            <ixz>0</ixz>
            <iyy>0.013</iyy>
            <iyz>0</iyz>
            <izz>0.013</izz>
          </inertia>
        </inertial>
        <collision name='left_fwheel_fixed_joint_lump__collision_collision'>
          <pose frame=''>0 0 0 3.14159 1.57079 -1.57089</pose>
          <geometry>
            <cylinder>
              <length>0.05</length>
              <radius>0.1</radius>
            </cylinder>
          </geometry>
          <max_contacts>10</max_contacts>
          <surface>
            <contact>
              <ode/>
            </contact>
            <bounce/>
            <friction>
              <torsional>
                <ode/>
              </torsional>
              <ode/>
            </friction>
          </surface>
        </collision>
        <visual name='left_fwheel_fixed_joint_lump__left_wheel_fvisual_visual'>
          <pose frame=''>0 0 0 3.14159 1.57079 -1.57089</pose>
          <geometry>
            <cylinder>
              <length>0.05</length>
              <radius>0.1</radius>
            </cylinder>
          </geometry>
        </visual>
        <self_collide>0</self_collide>
        <enable_wind>0</enable_wind>
        <kinematic>0</kinematic>
      </link>
      <joint name='left_wheel_fhinge' type='revolute'>
        <child>left_fwheel</child>
        <parent>chassis</parent>
        <axis>
          <xyz>0 1 0</xyz>
          <limit>
            <lower>-1e+16</lower>
            <upper>1e+16</upper>
          </limit>
          <dynamics>
            <spring_reference>0</spring_reference>
            <spring_stiffness>0</spring_stiffness>
          </dynamics>
          <use_parent_model_frame>1</use_parent_model_frame>
        </axis>
      </joint>
      <link name='left_wheel'>
        <pose frame=''>0.1 0.15 0 0 -0 0</pose>
        <inertial>
          <pose frame=''>0 0 0 -0 1.5707 1.5707</pose>
          <mass>5</mass>
          <inertia>
            <ixx>0.013</ixx>
            <ixy>0</ixy>
            <ixz>0</ixz>
            <iyy>0.013</iyy>
            <iyz>0</iyz>
            <izz>0.013</izz>
          </inertia>
        </inertial>
        <collision name='left_wheel_fixed_joint_lump__collision_collision'>
          <pose frame=''>0 0 0 3.14159 1.57079 -1.57089</pose>
          <geometry>
            <cylinder>
              <length>0.05</length>
              <radius>0.1</radius>
            </cylinder>
          </geometry>
          <max_contacts>10</max_contacts>
          <surface>
            <contact>
              <ode/>
            </contact>
            <bounce/>
            <friction>
              <torsional>
                <ode/>
              </torsional>
              <ode/>
            </friction>
          </surface>
        </collision>
        <visual name='left_wheel_visual_visual'>
          <pose frame=''>0 0 0 3.14159 1.57079 -1.57089</pose>
          <geometry>
            <cylinder>
              <length>0.05</length>
              <radius>0.1</radius>
            </cylinder>
          </geometry>
        </visual>
        <self_collide>0</self_collide>
        <enable_wind>0</enable_wind>
        <kinematic>0</kinematic>
      </link>
      <joint name='left_wheel_hinge' type='revolute'>
        <child>left_wheel</child>
        <parent>chassis</parent>
        <axis>
          <xyz>0 1 0</xyz>
          <limit>
            <lower>-1e+16</lower>
            <upper>1e+16</upper>
          </limit>
          <dynamics>
            <spring_reference>0</spring_reference>
            <spring_stiffness>0</spring_stiffness>
          </dynamics>
          <use_parent_model_frame>1</use_parent_model_frame>
        </axis>
      </joint>
      <link name='right_fwheel'>
        <pose frame=''>-0.1 -0.15 0 0 -0 0</pose>
        <inertial>
          <pose frame=''>0 0 0 -0 1.5707 1.5707</pose>
          <mass>5</mass>
          <inertia>
            <ixx>0.013</ixx>
            <ixy>0</ixy>
            <ixz>0</ixz>
            <iyy>0.013</iyy>
            <iyz>0</iyz>
            <izz>0.013</izz>
          </inertia>
        </inertial>
        <collision name='right_fwheel_fixed_joint_lump__collision_collision'>
          <pose frame=''>0 0 0 3.14159 1.57079 -1.57089</pose>
          <geometry>
            <cylinder>
              <length>0.05</length>
              <radius>0.1</radius>
            </cylinder>
          </geometry>
          <max_contacts>10</max_contacts>
          <surface>
            <contact>
              <ode/>
            </contact>
            <bounce/>
            <friction>
              <torsional>
                <ode/>
              </torsional>
              <ode/>
            </friction>
          </surface>
        </collision>
        <visual name='right_fwheel_fixed_joint_lump__right_wheel_fvisual_visual'>
          <pose frame=''>0 0 0 3.14159 1.57079 -1.57089</pose>
          <geometry>
            <cylinder>
              <length>0.05</length>
              <radius>0.1</radius>
            </cylinder>
          </geometry>
        </visual>
        <self_collide>0</self_collide>
        <enable_wind>0</enable_wind>
        <kinematic>0</kinematic>
      </link>
      <joint name='right_wheel_fhinge' type='revolute'>
        <child>right_fwheel</child>
        <parent>chassis</parent>
        <axis>
          <xyz>0 1 0</xyz>
          <limit>
            <lower>-1e+16</lower>
            <upper>1e+16</upper>
          </limit>
          <dynamics>
            <spring_reference>0</spring_reference>
            <spring_stiffness>0</spring_stiffness>
          </dynamics>
          <use_parent_model_frame>1</use_parent_model_frame>
        </axis>
      </joint>
      <link name='right_wheel'>
        <pose frame=''>0.1 -0.15 0 0 -0 0</pose>
        <inertial>
          <pose frame=''>0 0 0 -0 1.5707 1.5707</pose>
          <mass>5</mass>
          <inertia>
            <ixx>0.013</ixx>
            <ixy>0</ixy>
            <ixz>0</ixz>
            <iyy>0.013</iyy>
            <iyz>0</iyz>
            <izz>0.013</izz>
          </inertia>
        </inertial>
        <collision name='right_wheel_fixed_joint_lump__collision_collision'>
          <pose frame=''>0 0 0 3.14159 1.57079 -1.57089</pose>
          <geometry>
            <cylinder>
              <length>0.05</length>
              <radius>0.1</radius>
            </cylinder>
          </geometry>
          <max_contacts>10</max_contacts>
          <surface>
            <contact>
              <ode/>
            </contact>
            <bounce/>
            <friction>
              <torsional>
                <ode/>
              </torsional>
              <ode/>
            </friction>
          </surface>
        </collision>
        <visual name='right_wheel_visual_visual'>
          <pose frame=''>0 0 0 3.14159 1.57079 -1.57089</pose>
          <geometry>
            <cylinder>
              <length>0.05</length>
              <radius>0.1</radius>
            </cylinder>
          </geometry>
        </visual>
        <self_collide>0</self_collide>
        <enable_wind>0</enable_wind>
        <kinematic>0</kinematic>
      </link>
      <joint name='right_wheel_hinge' type='revolute'>
        <child>right_wheel</child>
        <parent>chassis</parent>
        <axis>
          <xyz>0 1 0</xyz>
          <limit>
            <lower>-1e+16</lower>
            <upper>1e+16</upper>
          </limit>
          <dynamics>
            <spring_reference>0</spring_reference>
            <spring_stiffness>0</spring_stiffness>
          </dynamics>
          <use_parent_model_frame>1</use_parent_model_frame>
        </axis>
      </joint>
      <plugin name='skid_steer_drive_controller' filename='libgazebo_ros_skid_steer_drive.so'>
        <updateRate>100.0</updateRate>
        <robotNamespace>/</robotNamespace>
        <leftFrontJoint>left_wheel_fhinge</leftFrontJoint>
        <rightFrontJoint>right_wheel_fhinge</rightFrontJoint>
        <leftRearJoint>left_wheel_hinge</leftRearJoint>
        <rightRearJoint>right_wheel_hinge</rightRearJoint>
        <wheelSeparation>0.1</wheelSeparation>
        <wheelDiameter>0.2</wheelDiameter>
        <commandTopic>cmd_vel</commandTopic>
        <robotBaseFrame>chassis</robotBaseFrame>
        <torque>20</torque>
        <odometryTopic>odom</odometryTopic>
        <odometryFrame>odom</odometryFrame>
        <topicName>cmd_vel</topicName>
        <broadcastTF>0</broadcastTF>
        <covariance_x>0</covariance_x>
        <covariance_y>0</covariance_y>
        <covariance_yaw>0</covariance_yaw>
      </plugin>
      <plugin name='imu' filename='libhector_gazebo_ros_imu.so'>
        <serviceName>/imu/calibrate</serviceName>
        <updateRate>200.0</updateRate>
        <bodyName>chassis</bodyName>
        <topicName>imu</topicName>
        <rpyOffset>0 0 0</rpyOffset>
        <xyzOffset>0 0 0</xyzOffset>
        <gaussianNoise>0.00000001</gaussianNoise>
        <accelDrift>0.00000001 0.00000001 0.00000001</accelDrift>
        <accelDriftFrequency>0.00000001 0.00000001 0.00000001</accelDriftFrequency>
        <accelGaussianNoise>0.00000001 0.00000001 0.00000001</accelGaussianNoise>
        <rateDrift>0.0 0.0 0.0</rateDrift>
        <rateDriftFrequency>0.0 0.0 0.0</rateDriftFrequency>
        <rateGaussianNoise>0.0 0.0 0.0</rateGaussianNoise>
        <headingDrift>0.0 0.0 0.0</headingDrift>
        <headingDriftFrequency>0.0 0.0 0.0</headingDriftFrequency>
        <headingGaussianNoise>0.0 0.0 0.0</headingGaussianNoise>
        <robotNamespace>/</robotNamespace>
      </plugin>
      <static>0</static>
      <plugin name='novatel_gps_sim' filename='libhector_gazebo_ros_gps.so'>
        <alwaysOn>1</alwaysOn>
        <updateRate>10.0</updateRate>
        <bodyName>chassis</bodyName>
        <topicName>fix</topicName>
        <velocityTopicName>fix_velocity</velocityTopicName>
        <drift>5.0 5.0 5.0</drift>
        <gaussianNoise>0.000 0.000 0.000</gaussianNoise>
        <velocityDrift>0 0 0</velocityDrift>
        <velocityGaussianNoise>0.000 0.000 0.000</velocityGaussianNoise>
        <robotNamespace>/</robotNamespace>
      </plugin>
      <pose frame=''>0 0 0 0 -0 0</pose>
    </model>
    <model name='unit_cylinder'>
      <pose frame=''>3.95852 3.87618 0.5 0 -0 0</pose>
      <link name='link'>
        <inertial>
          <mass>1</mass>
          <inertia>
            <ixx>0.145833</ixx>
            <ixy>0</ixy>
            <ixz>0</ixz>
            <iyy>0.145833</iyy>
            <iyz>0</iyz>
            <izz>0.125</izz>
          </inertia>
        </inertial>
        <collision name='collision'>
          <geometry>
            <cylinder>
              <radius>0.5</radius>
              <length>1</length>
            </cylinder>
          </geometry>
          <max_contacts>10</max_contacts>
          <surface>
            <contact>
              <ode/>
            </contact>
            <bounce/>
            <friction>
              <torsional>
                <ode/>
              </torsional>
              <ode/>
            </friction>
          </surface>
        </collision>
        <visual name='visual'>
          <geometry>
            <cylinder>
              <radius>0.5</radius>
              <length>1</length>
            </cylinder>
          </geometry>
          <material>
            <script>
              <name>Gazebo/Grey</name>
              <uri>file://media/materials/scripts/gazebo.material</uri>
            </script>
          </material>
        </visual>
        <self_collide>0</self_collide>
        <enable_wind>0</enable_wind>
        <kinematic>0</kinematic>
      </link>
    </model>
    <state world_name='default'>
      <sim_time>151 288000000</sim_time>
      <real_time>152 63384129</real_time>
      <wall_time>1609067111 625188140</wall_time>
      <iterations>151288</iterations>
      <model name='ground_plane'>
        <pose frame=''>0 0 0 0 -0 0</pose>
        <scale>1 1 1</scale>
        <link name='link'>
          <pose frame=''>0 0 0 0 -0 0</pose>
          <velocity>0 0 0 0 -0 0</velocity>
          <acceleration>0 0 0 0 -0 0</acceleration>
          <wrench>0 0 0 0 -0 0</wrench>
        </link>
      </model>
      <model name='rrt_bot'>
        <pose frame=''>0.01777 -0.023148 0.100001 0 -4e-06 -0.048161</pose>
        <scale>1 1 1</scale>
        <link name='chassis'>
          <pose frame=''>0.01777 -0.023148 0.100001 0 -4e-06 -0.048161</pose>
          <velocity>1.8e-05 0.000168 2.6e-05 -9.3e-05 -7.6e-05 -0.000833</velocity>
          <acceleration>0.012918 0.210193 -0.402582 3.04013 -0.132885 2.91244</acceleration>
          <wrench>0.193763 3.15289 -6.03873 0 -0 0</wrench>
        </link>
        <link name='left_fwheel'>
          <pose frame=''>-0.074892 0.131493 0.100001 -8e-06 -0.590641 -0.048154</pose>
          <velocity>8.9e-05 0.000261 -2.5e-05 0.001459 -0.000148 -0.001491</velocity>
          <acceleration>-0.259056 0.215583 -0.121485 1.87869 -1.27172 -0.619914</acceleration>
          <wrench>-1.29528 1.07791 -0.607424 0 -0 0</wrench>
        </link>
        <link name='left_wheel'>
          <pose frame=''>0.124875 0.121864 0.100002 -6e-06 0.721916 -0.048162</pose>
          <velocity>0.000193 4.9e-05 1e-06 -0.000453 0.002104 -0.000858</velocity>
          <acceleration>-0.056483 0.124117 -0.806242 -1.22392 -0.183558 -1.32161</acceleration>
          <wrench>-0.282417 0.620587 -4.03121 0 -0 0</wrench>
        </link>
        <link name='right_fwheel'>
          <pose frame=''>-0.089335 -0.168159 0.100001 1.6e-05 -0.363732 -0.048163</pose>
          <velocity>-0.000113 0.000171 -1.5e-05 -0.001757 -0.001432 -0.001315</velocity>
          <acceleration>-0.147245 0.141375 -0.105603 -1.37368 -1.10694 1.1855</acceleration>
          <wrench>-0.736225 0.706874 -0.528016 0 -0 0</wrench>
        </link>
        <link name='right_wheel'>
          <pose frame=''>0.110432 -0.177788 0.100001 1.3e-05 0.697991 -0.04815</pose>
          <velocity>3.1e-05 3e-05 9.6e-05 -0.002669 3.3e-05 -0.001574</velocity>
          <acceleration>-0.186152 0.084734 -0.649826 -0.027225 -1.12951 1.45683</acceleration>
          <wrench>-0.930758 0.423671 -3.24913 0 -0 0</wrench>
        </link>
      </model>
      <model name='unit_cylinder'>
        <pose frame=''>4.33948 4.00058 0.499991 -0 -0 -0.034062</pose>
        <scale>1 1 1</scale>
        <link name='link'>
          <pose frame=''>4.33948 4.00058 0.499991 -0 -0 -0.034062</pose>
          <velocity>0 0 0 0 -0 0</velocity>
          <acceleration>0 0 -9.8 0 -0 0</acceleration>
          <wrench>0 0 -9.8 0 -0 0</wrench>
        </link>
      </model>
      <light name='sun'>
        <pose frame=''>0 0 10 0 -0 0</pose>
      </light>
    </state>
    <gui fullscreen='0'>
      <camera name='user_camera'>
        <pose frame=''>-3.80623 -3.37074 5.95531 0 0.871642 0.780194</pose>
        <view_controller>orbit</view_controller>
        <projection_type>perspective</projection_type>
      </camera>
    </gui>
  </world>
</sdf>
